{
  "Software_Repo_MappingId": null,
  "Software_RepoId": "f6b863cd-8f1c-4583-8bc5-ee59e86e5cf1",
  "Software_Name": "Python 3.12.5 (64-bit)",
  "CVEID": "CVE-2018-1000030",
  "Summary": "Python 2.7.14 is vulnerable to a Heap-Buffer-Overflow as well as a Heap-Use-After-Free. Python versions prior to 2.7.14 may also be vulnerable and it appears that Python 2.7.17 and prior may also be vulnerable however this has not been confirmed. The vulnerability lies when multiply threads are handling large amounts of data. In both cases there is essentially a race condition that occurs. For the Heap-Buffer-Overflow, Thread 2 is creating the size for a buffer, but Thread1 is already writing to the buffer without knowing how much to write. So when a large amount of data is being processed, it is very easy to cause memory corruption using a Heap-Buffer-Overflow. As for the Use-After-Free, Thread3->Malloc->Thread1->Free's->Thread2-Re-uses-Free'd Memory. The PSRT has stated that this is not a security vulnerability due to the fact that the attacker must be able to run code, however in some situations, such as function as a service, this vulnerability can potentially be used by an attacker to violate a trust boundary, as such the DWF feels this issue deserves a CVE.",
  "LastUpdate": 0,
  "CVEE": {
    "CVEEId": "CVE-2018-1000030",
    "CVSS_V2_baseScore": 3.3,
    "CVSS_V2_Data": "{\"version\":\"2.0\",\"baseScore\":3.3,\"accessVector\":\"LOCAL\",\"vectorString\":\"AV:L/AC:M/Au:N/C:P/I:N/A:P\",\"authentication\":\"NONE\",\"integrityImpact\":\"NONE\",\"accessComplexity\":\"MEDIUM\",\"availabilityImpact\":\"PARTIAL\",\"confidentialityImpact\":\"PARTIAL\",\"scope\":null,\"attackVector\":null,\"baseSeverity\":null,\"userInteraction\":null,\"attackComplexity\":null,\"privilegesRequired\":null}",
    "CVSS_V3_baseScore": 3.6,
    "CVSS_V3_Data": "{\"version\":\"3.0\",\"baseScore\":3.6,\"accessVector\":null,\"vectorString\":\"CVSS:3.0/AV:L/AC:H/PR:L/UI:N/S:U/C:L/I:N/A:L\",\"authentication\":null,\"integrityImpact\":\"NONE\",\"accessComplexity\":null,\"availabilityImpact\":\"LOW\",\"confidentialityImpact\":\"LOW\",\"scope\":\"UNCHANGED\",\"attackVector\":\"LOCAL\",\"baseSeverity\":\"LOW\",\"userInteraction\":\"NONE\",\"attackComplexity\":\"HIGH\",\"privilegesRequired\":\"LOW\"}",
    "PublishedDate": "2018-02-08T17:29:00.177",
    "ModifyDate": "2024-11-21T03:39:28.167",
    "VulnStatus": "Modified",
    "JsonData": "{\"id\": \"CVE-2018-1000030\", \"summary\": \"Python 2.7.14 is vulnerable to a Heap-Buffer-Overflow as well as a Heap-Use-After-Free. Python versions prior to 2.7.14 may also be vulnerable and it appears that Python 2.7.17 and prior may also be vulnerable however this has not been confirmed. The vulnerability lies when multiply threads are handling large amounts of data. In both cases there is essentially a race condition that occurs. For the Heap-Buffer-Overflow, Thread 2 is creating the size for a buffer, but Thread1 is already writing to the buffer without knowing how much to write. So when a large amount of data is being processed, it is very easy to cause memory corruption using a Heap-Buffer-Overflow. As for the Use-After-Free, Thread3->Malloc->Thread1->Free's->Thread2-Re-uses-Free'd Memory. The PSRT has stated that this is not a security vulnerability due to the fact that the attacker must be able to run code, however in some situations, such as function as a service, this vulnerability can potentially be used by an attacker to violate a trust boundary, as such the DWF feels this issue deserves a CVE.\", \"created_at\": \"2018-02-08T17:29:00Z\", \"updated_at\": \"2024-11-21T03:39:28Z\", \"cvss\": {\"v2\": 3.3, \"v3\": 3.6}, \"vendors\": {\"python\": [\"python\"], \"canonical\": [\"ubuntu_linux\"]}, \"cwes\": [\"CWE-416\", \"CWE-787\"], \"raw_nvd_data\": {\"id\": \"CVE-2018-1000030\", \"metrics\": {\"cvssMetricV2\": [{\"type\": \"Primary\", \"source\": \"nvd@nist.gov\", \"cvssData\": {\"version\": \"2.0\", \"baseScore\": 3.3, \"accessVector\": \"LOCAL\", \"vectorString\": \"AV:L/AC:M/Au:N/C:P/I:N/A:P\", \"authentication\": \"NONE\", \"integrityImpact\": \"NONE\", \"accessComplexity\": \"MEDIUM\", \"availabilityImpact\": \"PARTIAL\", \"confidentialityImpact\": \"PARTIAL\"}, \"acInsufInfo\": false, \"impactScore\": 4.9, \"baseSeverity\": \"LOW\", \"obtainAllPrivilege\": false, \"exploitabilityScore\": 3.4, \"obtainUserPrivilege\": false, \"obtainOtherPrivilege\": false, \"userInteractionRequired\": false}], \"cvssMetricV30\": [{\"type\": \"Secondary\", \"source\": \"cve@mitre.org\", \"cvssData\": {\"scope\": \"UNCHANGED\", \"version\": \"3.0\", \"baseScore\": 3.6, \"attackVector\": \"LOCAL\", \"baseSeverity\": \"LOW\", \"vectorString\": \"CVSS:3.0/AV:L/AC:H/PR:L/UI:N/S:U/C:L/I:N/A:L\", \"integrityImpact\": \"NONE\", \"userInteraction\": \"NONE\", \"attackComplexity\": \"HIGH\", \"availabilityImpact\": \"LOW\", \"privilegesRequired\": \"LOW\", \"confidentialityImpact\": \"LOW\"}, \"impactScore\": 2.5, \"exploitabilityScore\": 1.0}], \"cvssMetricV31\": [{\"type\": \"Primary\", \"source\": \"nvd@nist.gov\", \"cvssData\": {\"scope\": \"UNCHANGED\", \"version\": \"3.1\", \"baseScore\": 3.6, \"attackVector\": \"LOCAL\", \"baseSeverity\": \"LOW\", \"vectorString\": \"CVSS:3.1/AV:L/AC:H/PR:L/UI:N/S:U/C:L/I:N/A:L\", \"integrityImpact\": \"NONE\", \"userInteraction\": \"NONE\", \"attackComplexity\": \"HIGH\", \"availabilityImpact\": \"LOW\", \"privilegesRequired\": \"LOW\", \"confidentialityImpact\": \"LOW\"}, \"impactScore\": 2.5, \"exploitabilityScore\": 1.0}]}, \"published\": \"2018-02-08T17:29:00.177\", \"references\": [{\"url\": \"https://bugs.python.org/issue31530\", \"tags\": [\"Issue Tracking\", \"Patch\", \"Vendor Advisory\"], \"source\": \"cve@mitre.org\"}, {\"url\": \"https://drive.google.com/file/d/1oyR9DAZjZK_SCn3mor6NRAYLJS6ueXaY/view\", \"tags\": [\"Third Party Advisory\"], \"source\": \"cve@mitre.org\"}, {\"url\": \"https://security.gentoo.org/glsa/201811-02\", \"tags\": [\"Third Party Advisory\"], \"source\": \"cve@mitre.org\"}, {\"url\": \"https://usn.ubuntu.com/3817-1/\", \"tags\": [\"Third Party Advisory\"], \"source\": \"cve@mitre.org\"}, {\"url\": \"https://usn.ubuntu.com/3817-2/\", \"tags\": [\"Third Party Advisory\"], \"source\": \"cve@mitre.org\"}, {\"url\": \"https://www.dropbox.com/sh/sj3ee7xv55j36k7/AADwP-YfOYikBMuy32e0uvPFa?dl=0\", \"tags\": [\"Permissions Required\"], \"source\": \"cve@mitre.org\"}, {\"url\": \"https://www.oracle.com/security-alerts/cpujan2020.html\", \"tags\": [\"Third Party Advisory\"], \"source\": \"cve@mitre.org\"}, {\"url\": \"https://bugs.python.org/issue31530\", \"tags\": [\"Issue Tracking\", \"Patch\", \"Vendor Advisory\"], \"source\": \"af854a3a-2127-422b-91ae-364da2661108\"}, {\"url\": \"https://drive.google.com/file/d/1oyR9DAZjZK_SCn3mor6NRAYLJS6ueXaY/view\", \"tags\": [\"Third Party Advisory\"], \"source\": \"af854a3a-2127-422b-91ae-364da2661108\"}, {\"url\": \"https://security.gentoo.org/glsa/201811-02\", \"tags\": [\"Third Party Advisory\"], \"source\": \"af854a3a-2127-422b-91ae-364da2661108\"}, {\"url\": \"https://usn.ubuntu.com/3817-1/\", \"tags\": [\"Third Party Advisory\"], \"source\": \"af854a3a-2127-422b-91ae-364da2661108\"}, {\"url\": \"https://usn.ubuntu.com/3817-2/\", \"tags\": [\"Third Party Advisory\"], \"source\": \"af854a3a-2127-422b-91ae-364da2661108\"}, {\"url\": \"https://www.dropbox.com/sh/sj3ee7xv55j36k7/AADwP-YfOYikBMuy32e0uvPFa?dl=0\", \"tags\": [\"Permissions Required\"], \"source\": \"af854a3a-2127-422b-91ae-364da2661108\"}, {\"url\": \"https://www.oracle.com/security-alerts/cpujan2020.html\", \"tags\": [\"Third Party Advisory\"], \"source\": \"af854a3a-2127-422b-91ae-364da2661108\"}], \"vulnStatus\": \"Modified\", \"weaknesses\": [{\"type\": \"Primary\", \"source\": \"nvd@nist.gov\", \"description\": [{\"lang\": \"en\", \"value\": \"CWE-416\"}, {\"lang\": \"en\", \"value\": \"CWE-787\"}]}], \"descriptions\": [{\"lang\": \"en\", \"value\": \"Python 2.7.14 is vulnerable to a Heap-Buffer-Overflow as well as a Heap-Use-After-Free. Python versions prior to 2.7.14 may also be vulnerable and it appears that Python 2.7.17 and prior may also be vulnerable however this has not been confirmed. The vulnerability lies when multiply threads are handling large amounts of data. In both cases there is essentially a race condition that occurs. For the Heap-Buffer-Overflow, Thread 2 is creating the size for a buffer, but Thread1 is already writing to the buffer without knowing how much to write. So when a large amount of data is being processed, it is very easy to cause memory corruption using a Heap-Buffer-Overflow. As for the Use-After-Free, Thread3->Malloc->Thread1->Free's->Thread2-Re-uses-Free'd Memory. The PSRT has stated that this is not a security vulnerability due to the fact that the attacker must be able to run code, however in some situations, such as function as a service, this vulnerability can potentially be used by an attacker to violate a trust boundary, as such the DWF feels this issue deserves a CVE.\"}, {\"lang\": \"es\", \"value\": \"Python 2.7.14 es vulnerable a un desbordamiento de b\\u00fafer y a un uso de memoria din\\u00e1mica (heap) previamente liberada. Las versiones de Python anteriores a la 2.7.14 tambi\\u00e9n podr\\u00edan ser vulnerables y, aunque esto a\\u00fan no se ha confirmado, las versiones 2.7.17 y anteriores de Python tambi\\u00e9n podr\\u00edan ser vulnerables. La vulnerabilidad aparece cuando m\\u00faltiples hilos gestionan grandes cantidades de datos. En ambos casos, ocurre esencialmente una condici\\u00f3n de carrera. Para el desbordamiento de b\\u00fafer, el hilo 2 crea el tama\\u00f1o para un b\\u00fafer, pero el hilo 1 ya est\\u00e1 escribiendo en el b\\u00fafer sin saber cu\\u00e1nto escribir. Por lo tanto, cuando se procesa una gran cantidad de datos,es muy f\\u00e1cil provocar una corrupci\\u00f3n de memoria mediante un desbordamiento de b\\u00fafer basado en memoria din\\u00e1mica (heap). En el caso del uso de memoria previamente liberada, Hilo3->Malloc->Hilo1->Liberaci\\u00f3n->Hilo2-reutiliza la memoria liberada. El PSRT ha indicado que esta no es una vulnerabilidad de seguridad debido al hecho de que un atacante debe ser capaz de ejecutar c\\u00f3digo. Sin embargo, en algunas situaciones, como la de las funciones como servicio, esta vulnerabilidad puede ser empleada por un atacante para infringir un l\\u00edmite de confianza, por lo que DWF cree que este problema debe tener un CVE.\"}], \"lastModified\": \"2024-11-21T03:39:28.167\", \"configurations\": [{\"nodes\": [{\"negate\": false, \"cpeMatch\": [{\"criteria\": \"cpe:2.3:a:python:python:*:*:*:*:*:*:*:*\", \"vulnerable\": true, \"matchCriteriaId\": \"01E5CF3F-CAB9-4E6D-9FA9-911D78D71F59\", \"versionEndIncluding\": \"2.7.14\"}], \"operator\": \"OR\"}]}, {\"nodes\": [{\"negate\": false, \"cpeMatch\": [{\"criteria\": \"cpe:2.3:o:canonical:ubuntu_linux:12.04:*:*:*:esm:*:*:*\", \"vulnerable\": true, \"matchCriteriaId\": \"8D305F7A-D159-4716-AB26-5E38BB5CD991\"}, {\"criteria\": \"cpe:2.3:o:canonical:ubuntu_linux:14.04:*:*:*:lts:*:*:*\", \"vulnerable\": true, \"matchCriteriaId\": \"B5A6F2F3-4894-4392-8296-3B8DD2679084\"}, {\"criteria\": \"cpe:2.3:o:canonical:ubuntu_linux:16.04:*:*:*:lts:*:*:*\", \"vulnerable\": true, \"matchCriteriaId\": \"F7016A2A-8365-4F1A-89A2-7A19F2BCAE5B\"}, {\"criteria\": \"cpe:2.3:o:canonical:ubuntu_linux:18.04:*:*:*:lts:*:*:*\", \"vulnerable\": true, \"matchCriteriaId\": \"23A7C53F-B80F-4E6A-AFA9-58EEA84BE11D\"}], \"operator\": \"OR\"}]}], \"sourceIdentifier\": \"cve@mitre.org\"}}\n",
    "LastUpdate": 0,
    "VendorL": [
      "python",
      "canonical"
    ],
    "ProductL": [
      "python",
      "ubuntu_linux"
    ],
    "Software_Repo_Mappings": []
  },
  "Software_Repo_Mapping_Conditions": [
    {
      "Software_Repo_Mapping_ConditionId": 0,
      "Software_Repo_MappingId": null,
      "Criteria": "cpe:2.3:a:python:python:*:*:*:*:*:*:*:*",
      "VersionEndExcluding": null,
      "VersionEndIncluding": "2.7.14",
      "VersionStartExcluding": null,
      "VersionStartIncluding": null,
      "Vulnerable": true,
      "Software_Repo_Mapping": null
    }
  ]
}