{
  "Software_Repo_MappingId": null,
  "Software_RepoId": "f6b863cd-8f1c-4583-8bc5-ee59e86e5cf1",
  "Software_Name": "Python 3.12.5 (64-bit)",
  "CVEID": "CVE-2018-20406",
  "Summary": "Modules/_pickle.c in Python before 3.7.1 has an integer overflow via a large LONG_BINPUT value that is mishandled during a \"resize to twice the size\" attempt. This issue might cause memory exhaustion, but is only relevant if the pickle format is used for serializing tens or hundreds of gigabytes of data. This issue is fixed in: v3.4.10, v3.4.10rc1; v3.5.10, v3.5.10rc1, v3.5.7, v3.5.7rc1, v3.5.8, v3.5.8rc1, v3.5.8rc2, v3.5.9; v3.6.10, v3.6.10rc1, v3.6.11, v3.6.11rc1, v3.6.12, v3.6.7, v3.6.7rc1, v3.6.7rc2, v3.6.8, v3.6.8rc1, v3.6.9, v3.6.9rc1; v3.7.1, v3.7.1rc1, v3.7.1rc2, v3.7.2, v3.7.2rc1, v3.7.3, v3.7.3rc1, v3.7.4, v3.7.4rc1, v3.7.4rc2, v3.7.5, v3.7.5rc1, v3.7.6, v3.7.6rc1, v3.7.7, v3.7.7rc1, v3.7.8, v3.7.8rc1, v3.7.9.",
  "LastUpdate": 0,
  "CVEE": {
    "CVEEId": "CVE-2018-20406",
    "CVSS_V2_baseScore": 5.0,
    "CVSS_V2_Data": "{\"version\":\"2.0\",\"baseScore\":5.0,\"accessVector\":\"NETWORK\",\"vectorString\":\"AV:N/AC:L/Au:N/C:N/I:N/A:P\",\"authentication\":\"NONE\",\"integrityImpact\":\"NONE\",\"accessComplexity\":\"LOW\",\"availabilityImpact\":\"PARTIAL\",\"confidentialityImpact\":\"NONE\",\"scope\":null,\"attackVector\":null,\"baseSeverity\":null,\"userInteraction\":null,\"attackComplexity\":null,\"privilegesRequired\":null}",
    "CVSS_V3_baseScore": 7.5,
    "CVSS_V3_Data": "{\"version\":\"3.0\",\"baseScore\":7.5,\"accessVector\":null,\"vectorString\":\"CVSS:3.0/AV:N/AC:L/PR:N/UI:N/S:U/C:N/I:N/A:H\",\"authentication\":null,\"integrityImpact\":\"NONE\",\"accessComplexity\":null,\"availabilityImpact\":\"HIGH\",\"confidentialityImpact\":\"NONE\",\"scope\":\"UNCHANGED\",\"attackVector\":\"NETWORK\",\"baseSeverity\":\"HIGH\",\"userInteraction\":\"NONE\",\"attackComplexity\":\"LOW\",\"privilegesRequired\":\"NONE\"}",
    "PublishedDate": "2018-12-23T23:29:00.307",
    "ModifyDate": "2024-11-21T04:01:25.52",
    "VulnStatus": "Modified",
    "JsonData": "{\"id\": \"CVE-2018-20406\", \"summary\": \"Modules/_pickle.c in Python before 3.7.1 has an integer overflow via a large LONG_BINPUT value that is mishandled during a \\\"resize to twice the size\\\" attempt. This issue might cause memory exhaustion, but is only relevant if the pickle format is used for serializing tens or hundreds of gigabytes of data. This issue is fixed in: v3.4.10, v3.4.10rc1; v3.5.10, v3.5.10rc1, v3.5.7, v3.5.7rc1, v3.5.8, v3.5.8rc1, v3.5.8rc2, v3.5.9; v3.6.10, v3.6.10rc1, v3.6.11, v3.6.11rc1, v3.6.12, v3.6.7, v3.6.7rc1, v3.6.7rc2, v3.6.8, v3.6.8rc1, v3.6.9, v3.6.9rc1; v3.7.1, v3.7.1rc1, v3.7.1rc2, v3.7.2, v3.7.2rc1, v3.7.3, v3.7.3rc1, v3.7.4, v3.7.4rc1, v3.7.4rc2, v3.7.5, v3.7.5rc1, v3.7.6, v3.7.6rc1, v3.7.7, v3.7.7rc1, v3.7.8, v3.7.8rc1, v3.7.9.\", \"created_at\": \"2018-12-23T23:29:00Z\", \"updated_at\": \"2024-11-21T04:01:25Z\", \"cvss\": {\"v2\": 5.0, \"v3\": 7.5}, \"vendors\": {\"python\": [\"python\"], \"debian\": [\"debian_linux\"], \"fedoraproject\": [\"fedora\"]}, \"cwes\": [\"CWE-190\"], \"raw_nvd_data\": {\"id\": \"CVE-2018-20406\", \"metrics\": {\"cvssMetricV2\": [{\"type\": \"Primary\", \"source\": \"nvd@nist.gov\", \"cvssData\": {\"version\": \"2.0\", \"baseScore\": 5.0, \"accessVector\": \"NETWORK\", \"vectorString\": \"AV:N/AC:L/Au:N/C:N/I:N/A:P\", \"authentication\": \"NONE\", \"integrityImpact\": \"NONE\", \"accessComplexity\": \"LOW\", \"availabilityImpact\": \"PARTIAL\", \"confidentialityImpact\": \"NONE\"}, \"acInsufInfo\": false, \"impactScore\": 2.9, \"baseSeverity\": \"MEDIUM\", \"obtainAllPrivilege\": false, \"exploitabilityScore\": 10.0, \"obtainUserPrivilege\": false, \"obtainOtherPrivilege\": false, \"userInteractionRequired\": false}], \"cvssMetricV30\": [{\"type\": \"Primary\", \"source\": \"nvd@nist.gov\", \"cvssData\": {\"scope\": \"UNCHANGED\", \"version\": \"3.0\", \"baseScore\": 7.5, \"attackVector\": \"NETWORK\", \"baseSeverity\": \"HIGH\", \"vectorString\": \"CVSS:3.0/AV:N/AC:L/PR:N/UI:N/S:U/C:N/I:N/A:H\", \"integrityImpact\": \"NONE\", \"userInteraction\": \"NONE\", \"attackComplexity\": \"LOW\", \"availabilityImpact\": \"HIGH\", \"privilegesRequired\": \"NONE\", \"confidentialityImpact\": \"NONE\"}, \"impactScore\": 3.6, \"exploitabilityScore\": 3.9}]}, \"published\": \"2018-12-23T23:29:00.307\", \"references\": [{\"url\": \"http://lists.opensuse.org/opensuse-security-announce/2020-01/msg00040.html\", \"source\": \"cve@mitre.org\"}, {\"url\": \"https://access.redhat.com/errata/RHSA-2019:3725\", \"source\": \"cve@mitre.org\"}, {\"url\": \"https://bugs.python.org/issue34656\", \"tags\": [\"Exploit\", \"Issue Tracking\", \"Patch\", \"Vendor Advisory\"], \"source\": \"cve@mitre.org\"}, {\"url\": \"https://github.com/python/cpython/commit/a4ae828ee416a66d8c7bf5ee71d653c2cc6a26dd\", \"tags\": [\"Patch\", \"Third Party Advisory\"], \"source\": \"cve@mitre.org\"}, {\"url\": \"https://lists.debian.org/debian-lts-announce/2019/02/msg00011.html\", \"tags\": [\"Mailing List\", \"Third Party Advisory\"], \"source\": \"cve@mitre.org\"}, {\"url\": \"https://lists.debian.org/debian-lts-announce/2020/07/msg00011.html\", \"source\": \"cve@mitre.org\"}, {\"url\": \"https://lists.fedoraproject.org/archives/list/package-announce%40lists.fedoraproject.org/message/46PVWY5LFP4BRPG3BVQ5QEEFYBVEXHCK/\", \"source\": \"cve@mitre.org\"}, {\"url\": \"https://lists.fedoraproject.org/archives/list/package-announce%40lists.fedoraproject.org/message/AEZ5IQT7OF7Q2NCGIVABOWYGKO7YU3NJ/\", \"source\": \"cve@mitre.org\"}, {\"url\": \"https://lists.fedoraproject.org/archives/list/package-announce%40lists.fedoraproject.org/message/D3LXPABKVLFYUHRYJPM3CSS5MS6FXKS7/\", \"source\": \"cve@mitre.org\"}, {\"url\": \"https://lists.fedoraproject.org/archives/list/package-announce%40lists.fedoraproject.org/message/ICBEGRHIPHWPG2VGYS6R4EVKVUUF4AQW/\", \"source\": \"cve@mitre.org\"}, {\"url\": \"https://lists.fedoraproject.org/archives/list/package-announce%40lists.fedoraproject.org/message/JSKPGPZQNTAULHW4UH63KGOOUIDE4RRB/\", \"source\": \"cve@mitre.org\"}, {\"url\": \"https://lists.fedoraproject.org/archives/list/package-announce%40lists.fedoraproject.org/message/TR6GCO3WTV4D5L23WTCBF275VE6BVNI3/\", \"source\": \"cve@mitre.org\"}, {\"url\": \"https://security.netapp.com/advisory/ntap-20190416-0010/\", \"source\": \"cve@mitre.org\"}, {\"url\": \"https://usn.ubuntu.com/4127-1/\", \"source\": \"cve@mitre.org\"}, {\"url\": \"https://usn.ubuntu.com/4127-2/\", \"source\": \"cve@mitre.org\"}, {\"url\": \"http://lists.opensuse.org/opensuse-security-announce/2020-01/msg00040.html\", \"source\": \"af854a3a-2127-422b-91ae-364da2661108\"}, {\"url\": \"https://access.redhat.com/errata/RHSA-2019:3725\", \"source\": \"af854a3a-2127-422b-91ae-364da2661108\"}, {\"url\": \"https://bugs.python.org/issue34656\", \"tags\": [\"Exploit\", \"Issue Tracking\", \"Patch\", \"Vendor Advisory\"], \"source\": \"af854a3a-2127-422b-91ae-364da2661108\"}, {\"url\": \"https://github.com/python/cpython/commit/a4ae828ee416a66d8c7bf5ee71d653c2cc6a26dd\", \"tags\": [\"Patch\", \"Third Party Advisory\"], \"source\": \"af854a3a-2127-422b-91ae-364da2661108\"}, {\"url\": \"https://lists.debian.org/debian-lts-announce/2019/02/msg00011.html\", \"tags\": [\"Mailing List\", \"Third Party Advisory\"], \"source\": \"af854a3a-2127-422b-91ae-364da2661108\"}, {\"url\": \"https://lists.debian.org/debian-lts-announce/2020/07/msg00011.html\", \"source\": \"af854a3a-2127-422b-91ae-364da2661108\"}, {\"url\": \"https://lists.fedoraproject.org/archives/list/package-announce%40lists.fedoraproject.org/message/46PVWY5LFP4BRPG3BVQ5QEEFYBVEXHCK/\", \"source\": \"af854a3a-2127-422b-91ae-364da2661108\"}, {\"url\": \"https://lists.fedoraproject.org/archives/list/package-announce%40lists.fedoraproject.org/message/AEZ5IQT7OF7Q2NCGIVABOWYGKO7YU3NJ/\", \"source\": \"af854a3a-2127-422b-91ae-364da2661108\"}, {\"url\": \"https://lists.fedoraproject.org/archives/list/package-announce%40lists.fedoraproject.org/message/D3LXPABKVLFYUHRYJPM3CSS5MS6FXKS7/\", \"source\": \"af854a3a-2127-422b-91ae-364da2661108\"}, {\"url\": \"https://lists.fedoraproject.org/archives/list/package-announce%40lists.fedoraproject.org/message/ICBEGRHIPHWPG2VGYS6R4EVKVUUF4AQW/\", \"source\": \"af854a3a-2127-422b-91ae-364da2661108\"}, {\"url\": \"https://lists.fedoraproject.org/archives/list/package-announce%40lists.fedoraproject.org/message/JSKPGPZQNTAULHW4UH63KGOOUIDE4RRB/\", \"source\": \"af854a3a-2127-422b-91ae-364da2661108\"}, {\"url\": \"https://lists.fedoraproject.org/archives/list/package-announce%40lists.fedoraproject.org/message/TR6GCO3WTV4D5L23WTCBF275VE6BVNI3/\", \"source\": \"af854a3a-2127-422b-91ae-364da2661108\"}, {\"url\": \"https://security.netapp.com/advisory/ntap-20190416-0010/\", \"source\": \"af854a3a-2127-422b-91ae-364da2661108\"}, {\"url\": \"https://usn.ubuntu.com/4127-1/\", \"source\": \"af854a3a-2127-422b-91ae-364da2661108\"}, {\"url\": \"https://usn.ubuntu.com/4127-2/\", \"source\": \"af854a3a-2127-422b-91ae-364da2661108\"}], \"vulnStatus\": \"Modified\", \"weaknesses\": [{\"type\": \"Primary\", \"source\": \"nvd@nist.gov\", \"description\": [{\"lang\": \"en\", \"value\": \"CWE-190\"}]}], \"descriptions\": [{\"lang\": \"en\", \"value\": \"Modules/_pickle.c in Python before 3.7.1 has an integer overflow via a large LONG_BINPUT value that is mishandled during a \\\"resize to twice the size\\\" attempt. This issue might cause memory exhaustion, but is only relevant if the pickle format is used for serializing tens or hundreds of gigabytes of data. This issue is fixed in: v3.4.10, v3.4.10rc1; v3.5.10, v3.5.10rc1, v3.5.7, v3.5.7rc1, v3.5.8, v3.5.8rc1, v3.5.8rc2, v3.5.9; v3.6.10, v3.6.10rc1, v3.6.11, v3.6.11rc1, v3.6.12, v3.6.7, v3.6.7rc1, v3.6.7rc2, v3.6.8, v3.6.8rc1, v3.6.9, v3.6.9rc1; v3.7.1, v3.7.1rc1, v3.7.1rc2, v3.7.2, v3.7.2rc1, v3.7.3, v3.7.3rc1, v3.7.4, v3.7.4rc1, v3.7.4rc2, v3.7.5, v3.7.5rc1, v3.7.6, v3.7.6rc1, v3.7.7, v3.7.7rc1, v3.7.8, v3.7.8rc1, v3.7.9.\"}, {\"lang\": \"es\", \"value\": \"Modules/_pickle.c en Python, en versiones anteriores a la 3.7.1, tiene un desbordamiento de enteros mediante un valor LONG_BINPUT largo que se gestiona de manera incorrecta durante un intento de \\\"redimensionar al tama\\u00f1o doble\\\". Este problema podr\\u00eda provocar el agotamiento de memoria, pero solo es relevante si el formato picke se emplea para serializar decenas o cientos de gigabytes de datos.Este problema est\\u00e1 resuelto en las versiones: v3.4.10, v3.4.10rc1; v3.5.10, v3.5.10rc1, v3.5.7, v3.5.7rc1, v3.5.8, v3.5.8rc1, v3. 5.8rc2, v3.5.9; v3.6.10, v3.6.10rc1, v3.6.11, v3.6.11rc1, v3.6.12, v3.6.7, v3.6.7rc1, v3.6.7rc2, v3.6.6. 8, v3.6.8rc1, v3.6.9, v3.6.9rc1; v3.7.1, v3.7.1rc1, v3.7.1rc2, v3.7.2, v3.7.2rc1, v3.7.3, v3.7.3rc1, v3.7. 4, v3.7.4rc1, v3.7.4rc2, v3.7.5, v3.7.5rc1, v3.7.6, v3.7.6rc1, v3.7.7, v3.7.7rc1, v3.7.8, v3.7.8rc1, v3.7.9.\"}], \"lastModified\": \"2024-11-21T04:01:25.520\", \"configurations\": [{\"nodes\": [{\"negate\": false, \"cpeMatch\": [{\"criteria\": \"cpe:2.3:a:python:python:*:*:*:*:*:*:*:*\", \"vulnerable\": true, \"matchCriteriaId\": \"FECA0AB3-E761-454E-A689-5A7BE1C44384\", \"versionEndExcluding\": \"3.7.1\", \"versionStartIncluding\": \"3.4.0\"}], \"operator\": \"OR\"}]}, {\"nodes\": [{\"negate\": false, \"cpeMatch\": [{\"criteria\": \"cpe:2.3:o:debian:debian_linux:8.0:*:*:*:*:*:*:*\", \"vulnerable\": true, \"matchCriteriaId\": \"C11E6FB0-C8C0-4527-9AA0-CB9B316F8F43\"}], \"operator\": \"OR\"}]}, {\"nodes\": [{\"negate\": false, \"cpeMatch\": [{\"criteria\": \"cpe:2.3:o:fedoraproject:fedora:28:*:*:*:*:*:*:*\", \"vulnerable\": true, \"matchCriteriaId\": \"DC1BD7B7-6D88-42B8-878E-F1318CA5FCAF\"}, {\"criteria\": \"cpe:2.3:o:fedoraproject:fedora:29:*:*:*:*:*:*:*\", \"vulnerable\": true, \"matchCriteriaId\": \"D100F7CE-FC64-4CC6-852A-6136D72DA419\"}, {\"criteria\": \"cpe:2.3:o:fedoraproject:fedora:30:*:*:*:*:*:*:*\", \"vulnerable\": true, \"matchCriteriaId\": \"97A4B8DF-58DA-4AB6-A1F9-331B36409BA3\"}], \"operator\": \"OR\"}]}], \"sourceIdentifier\": \"cve@mitre.org\"}}\n",
    "LastUpdate": 0,
    "VendorL": [
      "python",
      "debian",
      "fedoraproject"
    ],
    "ProductL": [
      "python",
      "debian_linux",
      "fedora"
    ],
    "Software_Repo_Mappings": []
  },
  "Software_Repo_Mapping_Conditions": [
    {
      "Software_Repo_Mapping_ConditionId": 0,
      "Software_Repo_MappingId": null,
      "Criteria": "cpe:2.3:a:python:python:*:*:*:*:*:*:*:*",
      "VersionEndExcluding": "3.7.1",
      "VersionEndIncluding": null,
      "VersionStartExcluding": null,
      "VersionStartIncluding": "3.4.0",
      "Vulnerable": true,
      "Software_Repo_Mapping": null
    }
  ]
}