{
  "Software_Repo_MappingId": null,
  "Software_RepoId": "f6b863cd-8f1c-4583-8bc5-ee59e86e5cf1",
  "Software_Name": "Python 3.12.5 (64-bit)",
  "CVEID": "CVE-2006-1542",
  "Summary": "Stack-based buffer overflow in Python 2.4.2 and earlier, running on Linux 2.6.12.5 under gcc 4.0.3 with libc 2.3.5, allows local users to cause a \"stack overflow,\" and possibly gain privileges, by running a script from a current working directory that has a long name, related to the realpath function.  NOTE: this might not be a vulnerability. However, the fact that it appears in a programming language interpreter could mean that some applications are affected, although attack scenarios might be limited because the attacker might already need to cross privilege boundaries to cause an exploitable program to be placed in a directory with a long name; or, depending on the method that Python uses to determine the current working directory, setuid applications might be affected.",
  "LastUpdate": 0,
  "CVEE": {
    "CVEEId": "CVE-2006-1542",
    "CVSS_V2_baseScore": 3.7,
    "CVSS_V2_Data": "{\"version\":\"2.0\",\"baseScore\":3.7,\"accessVector\":\"LOCAL\",\"vectorString\":\"AV:L/AC:H/Au:N/C:P/I:P/A:P\",\"authentication\":\"NONE\",\"integrityImpact\":\"PARTIAL\",\"accessComplexity\":\"HIGH\",\"availabilityImpact\":\"PARTIAL\",\"confidentialityImpact\":\"PARTIAL\",\"scope\":null,\"attackVector\":null,\"baseSeverity\":null,\"userInteraction\":null,\"attackComplexity\":null,\"privilegesRequired\":null}",
    "CVSS_V3_baseScore": null,
    "CVSS_V3_Data": null,
    "PublishedDate": "2006-03-30T11:02:00",
    "ModifyDate": "2024-11-21T00:09:08.217",
    "VulnStatus": "Modified",
    "JsonData": "{\"id\": \"CVE-2006-1542\", \"summary\": \"Stack-based buffer overflow in Python 2.4.2 and earlier, running on Linux 2.6.12.5 under gcc 4.0.3 with libc 2.3.5, allows local users to cause a \\\"stack overflow,\\\" and possibly gain privileges, by running a script from a current working directory that has a long name, related to the realpath function.  NOTE: this might not be a vulnerability. However, the fact that it appears in a programming language interpreter could mean that some applications are affected, although attack scenarios might be limited because the attacker might already need to cross privilege boundaries to cause an exploitable program to be placed in a directory with a long name; or, depending on the method that Python uses to determine the current working directory, setuid applications might be affected.\", \"created_at\": \"2006-03-30T11:02:00Z\", \"updated_at\": \"2024-11-21T00:09:08Z\", \"cvss\": {\"v2\": 3.7, \"v3\": null}, \"vendors\": {\"python\": [\"python\"]}, \"cwes\": [\"NVD-CWE-Other\"], \"raw_nvd_data\": {\"id\": \"CVE-2006-1542\", \"metrics\": {\"cvssMetricV2\": [{\"type\": \"Primary\", \"source\": \"nvd@nist.gov\", \"cvssData\": {\"version\": \"2.0\", \"baseScore\": 3.7, \"accessVector\": \"LOCAL\", \"vectorString\": \"AV:L/AC:H/Au:N/C:P/I:P/A:P\", \"authentication\": \"NONE\", \"integrityImpact\": \"PARTIAL\", \"accessComplexity\": \"HIGH\", \"availabilityImpact\": \"PARTIAL\", \"confidentialityImpact\": \"PARTIAL\"}, \"acInsufInfo\": false, \"impactScore\": 6.4, \"baseSeverity\": \"LOW\", \"obtainAllPrivilege\": false, \"exploitabilityScore\": 1.9, \"obtainUserPrivilege\": false, \"obtainOtherPrivilege\": true, \"userInteractionRequired\": false}]}, \"published\": \"2006-03-30T11:02:00.000\", \"references\": [{\"url\": \"http://secunia.com/advisories/31492\", \"tags\": [\"Broken Link\"], \"source\": \"cve@mitre.org\"}, {\"url\": \"http://www.gotfault.net/research/exploit/gexp-python.py\", \"tags\": [\"Exploit\"], \"source\": \"cve@mitre.org\"}, {\"url\": \"http://www.redhat.com/support/errata/RHSA-2008-0629.html\", \"tags\": [\"Third Party Advisory\"], \"source\": \"cve@mitre.org\"}, {\"url\": \"https://www.exploit-db.com/exploits/1591\", \"tags\": [\"Third Party Advisory\", \"VDB Entry\"], \"source\": \"cve@mitre.org\"}, {\"url\": \"http://secunia.com/advisories/31492\", \"tags\": [\"Broken Link\"], \"source\": \"af854a3a-2127-422b-91ae-364da2661108\"}, {\"url\": \"http://www.gotfault.net/research/exploit/gexp-python.py\", \"tags\": [\"Exploit\"], \"source\": \"af854a3a-2127-422b-91ae-364da2661108\"}, {\"url\": \"http://www.redhat.com/support/errata/RHSA-2008-0629.html\", \"tags\": [\"Third Party Advisory\"], \"source\": \"af854a3a-2127-422b-91ae-364da2661108\"}, {\"url\": \"https://www.exploit-db.com/exploits/1591\", \"tags\": [\"Third Party Advisory\", \"VDB Entry\"], \"source\": \"af854a3a-2127-422b-91ae-364da2661108\"}], \"vulnStatus\": \"Modified\", \"weaknesses\": [{\"type\": \"Primary\", \"source\": \"nvd@nist.gov\", \"description\": [{\"lang\": \"en\", \"value\": \"NVD-CWE-Other\"}]}], \"descriptions\": [{\"lang\": \"en\", \"value\": \"Stack-based buffer overflow in Python 2.4.2 and earlier, running on Linux 2.6.12.5 under gcc 4.0.3 with libc 2.3.5, allows local users to cause a \\\"stack overflow,\\\" and possibly gain privileges, by running a script from a current working directory that has a long name, related to the realpath function.  NOTE: this might not be a vulnerability. However, the fact that it appears in a programming language interpreter could mean that some applications are affected, although attack scenarios might be limited because the attacker might already need to cross privilege boundaries to cause an exploitable program to be placed in a directory with a long name; or, depending on the method that Python uses to determine the current working directory, setuid applications might be affected.\"}], \"lastModified\": \"2024-11-21T00:09:08.217\", \"configurations\": [{\"nodes\": [{\"negate\": false, \"cpeMatch\": [{\"criteria\": \"cpe:2.3:a:python:python:*:*:*:*:*:*:*:*\", \"vulnerable\": true, \"matchCriteriaId\": \"90C1DEDF-83D3-43A8-B716-8EC1AD2F7960\", \"versionEndIncluding\": \"2.4.2\"}], \"operator\": \"OR\"}]}], \"vendorComments\": [{\"comment\": \"Red Hat is aware of this issue and is tracking it via the following bug:\\nhttps://bugzilla.redhat.com/bugzilla/show_bug.cgi?id=187900\\n\\nThe Red Hat Security Response Team has rated this issue as having low security impact, a future update may address this flaw.  More information regarding issue severity can be found here:\\nhttp://www.redhat.com/security/updates/classification/\\n\\nRed Hat Enterprise Linux 5 is not vulnerable to this issue as it contains a backported patch.\", \"lastModified\": \"2007-03-14T00:00:00\", \"organization\": \"Red Hat\"}], \"sourceIdentifier\": \"cve@mitre.org\", \"evaluatorSolution\": \"Successful exploitation requires that the Python is running on Linux 2.6.12.5 under gcc 4.0.3 with libc 2.3.5\"}}\n",
    "LastUpdate": 0,
    "VendorL": [
      "python"
    ],
    "ProductL": [
      "python"
    ],
    "Software_Repo_Mappings": []
  },
  "Software_Repo_Mapping_Conditions": [
    {
      "Software_Repo_Mapping_ConditionId": 0,
      "Software_Repo_MappingId": null,
      "Criteria": "cpe:2.3:a:python:python:*:*:*:*:*:*:*:*",
      "VersionEndExcluding": null,
      "VersionEndIncluding": "2.4.2",
      "VersionStartExcluding": null,
      "VersionStartIncluding": null,
      "Vulnerable": true,
      "Software_Repo_Mapping": null
    }
  ]
}