{
  "Software_Repo_MappingId": null,
  "Software_RepoId": "f6b863cd-8f1c-4583-8bc5-ee59e86e5cf1",
  "Software_Name": "Python 3.12.5 (64-bit)",
  "CVEID": "CVE-2023-6507",
  "Summary": "An issue was found in CPython 3.12.0 `subprocess` module on POSIX platforms. The issue was fixed in CPython 3.12.1 and does not affect other stable releases.\n\nWhen using the `extra_groups=` parameter with an empty list as a value (ie `extra_groups=[]`) the logic regressed to not call `setgroups(0, NULL)` before calling `exec()`, thus not dropping the original processes' groups before starting the new process. There is no issue when the parameter isn't used or when any value is used besides an empty list.\n\nThis issue only impacts CPython processes run with sufficient privilege to make the `setgroups` system call (typically `root`).\n\n",
  "LastUpdate": 0,
  "CVEE": {
    "CVEEId": "CVE-2023-6507",
    "CVSS_V2_baseScore": null,
    "CVSS_V2_Data": null,
    "CVSS_V3_baseScore": 6.1,
    "CVSS_V3_Data": "{\"version\":\"3.1\",\"baseScore\":6.1,\"accessVector\":null,\"vectorString\":\"CVSS:3.1/AV:A/AC:L/PR:H/UI:N/S:U/C:H/I:H/A:N\",\"authentication\":null,\"integrityImpact\":\"HIGH\",\"accessComplexity\":null,\"availabilityImpact\":\"NONE\",\"confidentialityImpact\":\"HIGH\",\"scope\":\"UNCHANGED\",\"attackVector\":\"ADJACENT_NETWORK\",\"baseSeverity\":\"MEDIUM\",\"userInteraction\":\"NONE\",\"attackComplexity\":\"LOW\",\"privilegesRequired\":\"HIGH\"}",
    "PublishedDate": "2023-12-08T19:15:08.44",
    "ModifyDate": "2024-11-21T08:43:59.623",
    "VulnStatus": "Modified",
    "JsonData": "{\"id\": \"CVE-2023-6507\", \"summary\": \"An issue was found in CPython 3.12.0 `subprocess` module on POSIX platforms. The issue was fixed in CPython 3.12.1 and does not affect other stable releases.\\n\\nWhen using the `extra_groups=` parameter with an empty list as a value (ie `extra_groups=[]`) the logic regressed to not call `setgroups(0, NULL)` before calling `exec()`, thus not dropping the original processes' groups before starting the new process. There is no issue when the parameter isn't used or when any value is used besides an empty list.\\n\\nThis issue only impacts CPython processes run with sufficient privilege to make the `setgroups` system call (typically `root`).\\n\\n\", \"created_at\": \"2023-12-08T19:15:08Z\", \"updated_at\": \"2024-11-21T08:43:59Z\", \"cvss\": {\"v2\": null, \"v3\": 6.1}, \"vendors\": {\"python\": [\"python\"]}, \"cwes\": [\"NVD-CWE-noinfo\", \"CWE-269\"], \"raw_nvd_data\": {\"id\": \"CVE-2023-6507\", \"metrics\": {\"cvssMetricV31\": [{\"type\": \"Secondary\", \"source\": \"cna@python.org\", \"cvssData\": {\"scope\": \"UNCHANGED\", \"version\": \"3.1\", \"baseScore\": 6.1, \"attackVector\": \"ADJACENT_NETWORK\", \"baseSeverity\": \"MEDIUM\", \"vectorString\": \"CVSS:3.1/AV:A/AC:L/PR:H/UI:N/S:U/C:H/I:H/A:N\", \"integrityImpact\": \"HIGH\", \"userInteraction\": \"NONE\", \"attackComplexity\": \"LOW\", \"availabilityImpact\": \"NONE\", \"privilegesRequired\": \"HIGH\", \"confidentialityImpact\": \"HIGH\"}, \"impactScore\": 5.2, \"exploitabilityScore\": 0.9}, {\"type\": \"Primary\", \"source\": \"nvd@nist.gov\", \"cvssData\": {\"scope\": \"UNCHANGED\", \"version\": \"3.1\", \"baseScore\": 4.9, \"attackVector\": \"NETWORK\", \"baseSeverity\": \"MEDIUM\", \"vectorString\": \"CVSS:3.1/AV:N/AC:L/PR:H/UI:N/S:U/C:N/I:H/A:N\", \"integrityImpact\": \"HIGH\", \"userInteraction\": \"NONE\", \"attackComplexity\": \"LOW\", \"availabilityImpact\": \"NONE\", \"privilegesRequired\": \"HIGH\", \"confidentialityImpact\": \"NONE\"}, \"impactScore\": 3.6, \"exploitabilityScore\": 1.2}]}, \"published\": \"2023-12-08T19:15:08.440\", \"references\": [{\"url\": \"https://github.com/python/cpython/commit/10e9bb13b8dcaa414645b9bd10718d8f7179e82b\", \"source\": \"cna@python.org\"}, {\"url\": \"https://github.com/python/cpython/commit/85bbfa8a4bbdbb61a3a84fbd7cb29a4096ab8a06\", \"source\": \"cna@python.org\"}, {\"url\": \"https://github.com/python/cpython/commit/9fe7655c6ce0b8e9adc229daf681b6d30e6b1610\", \"source\": \"cna@python.org\"}, {\"url\": \"https://github.com/python/cpython/issues/112334\", \"tags\": [\"Issue Tracking\", \"Patch\"], \"source\": \"cna@python.org\"}, {\"url\": \"https://mail.python.org/archives/list/security-announce@python.org/thread/AUL7QFHBLILGISS7U63B47AYSSGJJQZD/\", \"tags\": [\"Third Party Advisory\"], \"source\": \"cna@python.org\"}, {\"url\": \"https://github.com/python/cpython/commit/10e9bb13b8dcaa414645b9bd10718d8f7179e82b\", \"source\": \"af854a3a-2127-422b-91ae-364da2661108\"}, {\"url\": \"https://github.com/python/cpython/commit/85bbfa8a4bbdbb61a3a84fbd7cb29a4096ab8a06\", \"source\": \"af854a3a-2127-422b-91ae-364da2661108\"}, {\"url\": \"https://github.com/python/cpython/commit/9fe7655c6ce0b8e9adc229daf681b6d30e6b1610\", \"source\": \"af854a3a-2127-422b-91ae-364da2661108\"}, {\"url\": \"https://github.com/python/cpython/issues/112334\", \"tags\": [\"Issue Tracking\", \"Patch\"], \"source\": \"af854a3a-2127-422b-91ae-364da2661108\"}, {\"url\": \"https://mail.python.org/archives/list/security-announce@python.org/thread/AUL7QFHBLILGISS7U63B47AYSSGJJQZD/\", \"tags\": [\"Third Party Advisory\"], \"source\": \"af854a3a-2127-422b-91ae-364da2661108\"}], \"vulnStatus\": \"Modified\", \"weaknesses\": [{\"type\": \"Secondary\", \"source\": \"cna@python.org\", \"description\": [{\"lang\": \"en\", \"value\": \"CWE-269\"}]}, {\"type\": \"Primary\", \"source\": \"nvd@nist.gov\", \"description\": [{\"lang\": \"en\", \"value\": \"NVD-CWE-noinfo\"}]}], \"descriptions\": [{\"lang\": \"en\", \"value\": \"An issue was found in CPython 3.12.0 `subprocess` module on POSIX platforms. The issue was fixed in CPython 3.12.1 and does not affect other stable releases.\\n\\nWhen using the `extra_groups=` parameter with an empty list as a value (ie `extra_groups=[]`) the logic regressed to not call `setgroups(0, NULL)` before calling `exec()`, thus not dropping the original processes' groups before starting the new process. There is no issue when the parameter isn't used or when any value is used besides an empty list.\\n\\nThis issue only impacts CPython processes run with sufficient privilege to make the `setgroups` system call (typically `root`).\\n\\n\"}, {\"lang\": \"es\", \"value\": \"Se encontr\\u00f3 un problema en el m\\u00f3dulo `subproceso` de CPython 3.12.0 en plataformas POSIX. El problema se solucion\\u00f3 en CPython 3.12.1 y no afecta a otras versiones estables. Cuando se utiliza el par\\u00e1metro `extra_groups=` con una lista vac\\u00eda como valor (es decir, `extra_groups=[]`), la l\\u00f3gica retrocede para no llamar a `setgroups(0, NULL)` antes de llamar a `exec()`, por lo que no se descarta el grupos de procesos originales antes de iniciar el nuevo proceso. No hay ning\\u00fan problema cuando no se usa el par\\u00e1metro o cuando se usa cualquier valor adem\\u00e1s de una lista vac\\u00eda. Este problema solo afecta los procesos de CPython que se ejecutan con privilegios suficientes para realizar la llamada al sistema \\\"setgroups\\\" (normalmente \\\"root\\\").\"}], \"lastModified\": \"2024-11-21T08:43:59.623\", \"configurations\": [{\"nodes\": [{\"negate\": false, \"cpeMatch\": [{\"criteria\": \"cpe:2.3:a:python:python:3.12.0:-:*:*:*:*:*:*\", \"vulnerable\": true, \"matchCriteriaId\": \"5C76EDC2-43FF-448B-B65C-20AC83D680FE\"}, {\"criteria\": \"cpe:2.3:a:python:python:3.13.0:alpha1:*:*:*:*:*:*\", \"vulnerable\": true, \"matchCriteriaId\": \"978582FF-B8F3-479F-AE77-359E9AEE6F23\"}, {\"criteria\": \"cpe:2.3:a:python:python:3.13.0:alpha2:*:*:*:*:*:*\", \"vulnerable\": true, \"matchCriteriaId\": \"84E3F62C-7218-4DC3-8473-8A576739643A\"}], \"operator\": \"OR\"}]}], \"sourceIdentifier\": \"cna@python.org\"}}\n",
    "LastUpdate": 0,
    "VendorL": [
      "python"
    ],
    "ProductL": [
      "python"
    ],
    "Software_Repo_Mappings": []
  },
  "Software_Repo_Mapping_Conditions": [
    {
      "Software_Repo_Mapping_ConditionId": 0,
      "Software_Repo_MappingId": null,
      "Criteria": "cpe:2.3:a:python:python:3.12.0:-:*:*:*:*:*:*",
      "VersionEndExcluding": null,
      "VersionEndIncluding": null,
      "VersionStartExcluding": null,
      "VersionStartIncluding": null,
      "Vulnerable": true,
      "Software_Repo_Mapping": null
    },
    {
      "Software_Repo_Mapping_ConditionId": 0,
      "Software_Repo_MappingId": null,
      "Criteria": "cpe:2.3:a:python:python:3.13.0:alpha1:*:*:*:*:*:*",
      "VersionEndExcluding": null,
      "VersionEndIncluding": null,
      "VersionStartExcluding": null,
      "VersionStartIncluding": null,
      "Vulnerable": true,
      "Software_Repo_Mapping": null
    },
    {
      "Software_Repo_Mapping_ConditionId": 0,
      "Software_Repo_MappingId": null,
      "Criteria": "cpe:2.3:a:python:python:3.13.0:alpha2:*:*:*:*:*:*",
      "VersionEndExcluding": null,
      "VersionEndIncluding": null,
      "VersionStartExcluding": null,
      "VersionStartIncluding": null,
      "Vulnerable": true,
      "Software_Repo_Mapping": null
    }
  ]
}