{
  "Software_Repo_MappingId": null,
  "Software_RepoId": "f6b863cd-8f1c-4583-8bc5-ee59e86e5cf1",
  "Software_Name": "Python 3.12.5 (64-bit)",
  "CVEID": "CVE-2010-3492",
  "Summary": "The asyncore module in Python before 3.2 does not properly handle unsuccessful calls to the accept function, and does not have accompanying documentation describing how daemon applications should handle unsuccessful calls to the accept function, which makes it easier for remote attackers to conduct denial of service attacks that terminate these applications via network connections.",
  "LastUpdate": 0,
  "CVEE": {
    "CVEEId": "CVE-2010-3492",
    "CVSS_V2_baseScore": 5.0,
    "CVSS_V2_Data": "{\"version\":\"2.0\",\"baseScore\":5.0,\"accessVector\":\"NETWORK\",\"vectorString\":\"AV:N/AC:L/Au:N/C:N/I:N/A:P\",\"authentication\":\"NONE\",\"integrityImpact\":\"NONE\",\"accessComplexity\":\"LOW\",\"availabilityImpact\":\"PARTIAL\",\"confidentialityImpact\":\"NONE\",\"scope\":null,\"attackVector\":null,\"baseSeverity\":null,\"userInteraction\":null,\"attackComplexity\":null,\"privilegesRequired\":null}",
    "CVSS_V3_baseScore": null,
    "CVSS_V3_Data": null,
    "PublishedDate": "2010-10-19T20:00:04.237",
    "ModifyDate": "2024-11-21T01:18:51.587",
    "VulnStatus": "Modified",
    "JsonData": "{\"id\": \"CVE-2010-3492\", \"summary\": \"The asyncore module in Python before 3.2 does not properly handle unsuccessful calls to the accept function, and does not have accompanying documentation describing how daemon applications should handle unsuccessful calls to the accept function, which makes it easier for remote attackers to conduct denial of service attacks that terminate these applications via network connections.\", \"created_at\": \"2010-10-19T20:00:04Z\", \"updated_at\": \"2024-11-21T01:18:51Z\", \"cvss\": {\"v2\": 5.0, \"v3\": null}, \"vendors\": {\"python\": [\"python\"]}, \"cwes\": [\"NVD-CWE-Other\"], \"raw_nvd_data\": {\"id\": \"CVE-2010-3492\", \"metrics\": {\"cvssMetricV2\": [{\"type\": \"Primary\", \"source\": \"nvd@nist.gov\", \"cvssData\": {\"version\": \"2.0\", \"baseScore\": 5.0, \"accessVector\": \"NETWORK\", \"vectorString\": \"AV:N/AC:L/Au:N/C:N/I:N/A:P\", \"authentication\": \"NONE\", \"integrityImpact\": \"NONE\", \"accessComplexity\": \"LOW\", \"availabilityImpact\": \"PARTIAL\", \"confidentialityImpact\": \"NONE\"}, \"acInsufInfo\": false, \"impactScore\": 2.9, \"baseSeverity\": \"MEDIUM\", \"obtainAllPrivilege\": false, \"exploitabilityScore\": 10.0, \"obtainUserPrivilege\": false, \"obtainOtherPrivilege\": false, \"userInteractionRequired\": false}]}, \"published\": \"2010-10-19T20:00:04.237\", \"references\": [{\"url\": \"http://bugs.python.org/issue6706\", \"tags\": [\"Patch\", \"Vendor Advisory\"], \"source\": \"cve@mitre.org\"}, {\"url\": \"http://www.mandriva.com/security/advisories?name=MDVSA-2010:215\", \"tags\": [\"Third Party Advisory\"], \"source\": \"cve@mitre.org\"}, {\"url\": \"http://www.mandriva.com/security/advisories?name=MDVSA-2010:216\", \"tags\": [\"Third Party Advisory\"], \"source\": \"cve@mitre.org\"}, {\"url\": \"http://www.openwall.com/lists/oss-security/2010/09/09/6\", \"tags\": [\"Mailing List\", \"Third Party Advisory\"], \"source\": \"cve@mitre.org\"}, {\"url\": \"http://www.openwall.com/lists/oss-security/2010/09/11/2\", \"tags\": [\"Mailing List\", \"Third Party Advisory\"], \"source\": \"cve@mitre.org\"}, {\"url\": \"http://www.openwall.com/lists/oss-security/2010/09/22/3\", \"tags\": [\"Mailing List\", \"Third Party Advisory\"], \"source\": \"cve@mitre.org\"}, {\"url\": \"http://www.openwall.com/lists/oss-security/2010/09/24/3\", \"tags\": [\"Mailing List\", \"Third Party Advisory\"], \"source\": \"cve@mitre.org\"}, {\"url\": \"https://oval.cisecurity.org/repository/search/definition/oval%3Aorg.mitre.oval%3Adef%3A12111\", \"tags\": [\"Third Party Advisory\"], \"source\": \"cve@mitre.org\"}, {\"url\": \"http://bugs.python.org/issue6706\", \"tags\": [\"Patch\", \"Vendor Advisory\"], \"source\": \"af854a3a-2127-422b-91ae-364da2661108\"}, {\"url\": \"http://www.mandriva.com/security/advisories?name=MDVSA-2010:215\", \"tags\": [\"Third Party Advisory\"], \"source\": \"af854a3a-2127-422b-91ae-364da2661108\"}, {\"url\": \"http://www.mandriva.com/security/advisories?name=MDVSA-2010:216\", \"tags\": [\"Third Party Advisory\"], \"source\": \"af854a3a-2127-422b-91ae-364da2661108\"}, {\"url\": \"http://www.openwall.com/lists/oss-security/2010/09/09/6\", \"tags\": [\"Mailing List\", \"Third Party Advisory\"], \"source\": \"af854a3a-2127-422b-91ae-364da2661108\"}, {\"url\": \"http://www.openwall.com/lists/oss-security/2010/09/11/2\", \"tags\": [\"Mailing List\", \"Third Party Advisory\"], \"source\": \"af854a3a-2127-422b-91ae-364da2661108\"}, {\"url\": \"http://www.openwall.com/lists/oss-security/2010/09/22/3\", \"tags\": [\"Mailing List\", \"Third Party Advisory\"], \"source\": \"af854a3a-2127-422b-91ae-364da2661108\"}, {\"url\": \"http://www.openwall.com/lists/oss-security/2010/09/24/3\", \"tags\": [\"Mailing List\", \"Third Party Advisory\"], \"source\": \"af854a3a-2127-422b-91ae-364da2661108\"}, {\"url\": \"https://oval.cisecurity.org/repository/search/definition/oval%3Aorg.mitre.oval%3Adef%3A12111\", \"tags\": [\"Third Party Advisory\"], \"source\": \"af854a3a-2127-422b-91ae-364da2661108\"}], \"vulnStatus\": \"Modified\", \"weaknesses\": [{\"type\": \"Primary\", \"source\": \"nvd@nist.gov\", \"description\": [{\"lang\": \"en\", \"value\": \"NVD-CWE-Other\"}]}], \"descriptions\": [{\"lang\": \"en\", \"value\": \"The asyncore module in Python before 3.2 does not properly handle unsuccessful calls to the accept function, and does not have accompanying documentation describing how daemon applications should handle unsuccessful calls to the accept function, which makes it easier for remote attackers to conduct denial of service attacks that terminate these applications via network connections.\"}, {\"lang\": \"es\", \"value\": \"El m\\u00f3dulo asyncore en Python anterior a v3.2 no controla correctamente llamadas fallidas a la funci\\u00f3n accept, y no tiene la documentaci\\u00f3n adjunta que describa c\\u00f3mo las aplicaciones demonio atienden las llamadas sin \\u00e9xito a la funci\\u00f3n accept, lo cual facilita a  atacantes remotos realizar ataques de denegaci\\u00f3n de servicio que terminan estas aplicaciones a trav\\u00e9s de conexiones de red.\"}], \"lastModified\": \"2024-11-21T01:18:51.587\", \"configurations\": [{\"nodes\": [{\"negate\": false, \"cpeMatch\": [{\"criteria\": \"cpe:2.3:a:python:python:*:*:*:*:*:*:*:*\", \"vulnerable\": true, \"matchCriteriaId\": \"5C7AE3F2-A21B-4F96-A7F5-6B105A8CE540\", \"versionEndIncluding\": \"2.7\"}, {\"criteria\": \"cpe:2.3:a:python:python:*:*:*:*:*:*:*:*\", \"vulnerable\": true, \"matchCriteriaId\": \"CF69B7D8-20B0-44E3-9AE8-BD29691EE13E\", \"versionEndExcluding\": \"3.1.2\", \"versionStartIncluding\": \"3.0\"}], \"operator\": \"OR\"}]}], \"sourceIdentifier\": \"cve@mitre.org\"}}\n",
    "LastUpdate": 0,
    "VendorL": [
      "python"
    ],
    "ProductL": [
      "python"
    ],
    "Software_Repo_Mappings": []
  },
  "Software_Repo_Mapping_Conditions": [
    {
      "Software_Repo_Mapping_ConditionId": 0,
      "Software_Repo_MappingId": null,
      "Criteria": "cpe:2.3:a:python:python:*:*:*:*:*:*:*:*",
      "VersionEndExcluding": null,
      "VersionEndIncluding": "2.7",
      "VersionStartExcluding": null,
      "VersionStartIncluding": null,
      "Vulnerable": true,
      "Software_Repo_Mapping": null
    },
    {
      "Software_Repo_Mapping_ConditionId": 0,
      "Software_Repo_MappingId": null,
      "Criteria": "cpe:2.3:a:python:python:*:*:*:*:*:*:*:*",
      "VersionEndExcluding": "3.1.2",
      "VersionEndIncluding": null,
      "VersionStartExcluding": null,
      "VersionStartIncluding": "3.0",
      "Vulnerable": true,
      "Software_Repo_Mapping": null
    }
  ]
}